Traceback (most recent call last):
  File "/opt/hostedtoolcache/Python/3.8.15/x64/lib/python3.8/site-packages/jupyter_cache/executors/utils.py", line 51, in single_nb_execution
    executenb(
  File "/opt/hostedtoolcache/Python/3.8.15/x64/lib/python3.8/site-packages/nbclient/client.py", line 1204, in execute
    return NotebookClient(nb=nb, resources=resources, km=km, **kwargs).execute()
  File "/opt/hostedtoolcache/Python/3.8.15/x64/lib/python3.8/site-packages/nbclient/util.py", line 84, in wrapped
    return just_run(coro(*args, **kwargs))
  File "/opt/hostedtoolcache/Python/3.8.15/x64/lib/python3.8/site-packages/nbclient/util.py", line 62, in just_run
    return loop.run_until_complete(coro)
  File "/opt/hostedtoolcache/Python/3.8.15/x64/lib/python3.8/asyncio/base_events.py", line 616, in run_until_complete
    return future.result()
  File "/opt/hostedtoolcache/Python/3.8.15/x64/lib/python3.8/site-packages/nbclient/client.py", line 663, in async_execute
    await self.async_execute_cell(
  File "/opt/hostedtoolcache/Python/3.8.15/x64/lib/python3.8/site-packages/nbclient/client.py", line 965, in async_execute_cell
    await self._check_raise_for_error(cell, cell_index, exec_reply)
  File "/opt/hostedtoolcache/Python/3.8.15/x64/lib/python3.8/site-packages/nbclient/client.py", line 862, in _check_raise_for_error
    raise CellExecutionError.from_cell_and_msg(cell, exec_reply_content)
nbclient.exceptions.CellExecutionError: An error occurred while executing the following cell:
------------------
def imshow(imgs):
    imgs = imgs / 2 + 0.5  # unnormalise back to [0,1]
    plt.imshow(np.transpose(torchvision.utils.make_grid(imgs).numpy(), (1, 2, 0)))
    plt.show()


dataiter = iter(train_loader)
images, labels = dataiter.next()  # get a batch of images
imshow(images)  # show images
print(
    " ".join("%5s" % train_dataset.classes[labels[j]] for j in range(batch_size))
)  # print labels
------------------

[0;31m---------------------------------------------------------------------------[0m
[0;31mAttributeError[0m                            Traceback (most recent call last)
Cell [0;32mIn[7], line 8[0m
[1;32m      4[0m     plt[38;5;241m.[39mshow()
[1;32m      7[0m dataiter [38;5;241m=[39m [38;5;28miter[39m(train_loader)
[0;32m----> 8[0m images, labels [38;5;241m=[39m [43mdataiter[49m[38;5;241;43m.[39;49m[43mnext[49m()  [38;5;66;03m# get a batch of images[39;00m
[1;32m      9[0m imshow(images)  [38;5;66;03m# show images[39;00m
[1;32m     10[0m [38;5;28mprint[39m(
[1;32m     11[0m     [38;5;124m"[39m[38;5;124m [39m[38;5;124m"[39m[38;5;241m.[39mjoin([38;5;124m"[39m[38;5;132;01m%5s[39;00m[38;5;124m"[39m [38;5;241m%[39m train_dataset[38;5;241m.[39mclasses[labels[j]] [38;5;28;01mfor[39;00m j [38;5;129;01min[39;00m [38;5;28mrange[39m(batch_size))
[1;32m     12[0m )  [38;5;66;03m# print labels[39;00m

[0;31mAttributeError[0m: '_MultiProcessingDataLoaderIter' object has no attribute 'next'
AttributeError: '_MultiProcessingDataLoaderIter' object has no attribute 'next'

